<?xml version='1.0' encoding='utf-8'?>
<robot name="arm_urdf">
    <link name="base_link">
        <inertial>
            <origin xyz="-4.505944228849788e-18 -2.470246229790991e-17 0.0050000000000000626" rpy="0.0 0.0 0.0" />
            <mass value="4.90625" />
            <inertia ixx="0.025594270833334307" iyy="0.025594270833333974" izz="0.0511067708333343" ixy="-2.897344184594639e-16" iyz="-5.296012949210774e-16" ixz="1.4029557065788213e-17" />
        </inertial>
        <visual name="base_link_visual">
            <origin xyz="0.0 0.0 0.0" rpy="0.0 0.0 0.0" />
            <geometry>
                <mesh filename="file://$(find arm_urdf)/meshes/base_link.stl" scale="0.001 0.001 0.001" />
            </geometry>
        </visual>
        <collision name="base_link_collision">
            <origin xyz="0.0 0.0 0.0" rpy="0.0 0.0 0.0" />
            <geometry>
                <mesh filename="file://$(find arm_urdf)/meshes/base_link.stl" scale="0.001 0.001 0.001" />
            </geometry>
        </collision>
    </link>
    <link name="link1">
        <inertial>
            <origin xyz="7.400736024010258e-10 -2.0424169377974977e-09 0.024999998493530313" rpy="0.0 -0.0 0.0" />
            <mass value="0.35324999999999995" />
            <inertia ixx="0.0001000875000001164" iyy="0.0001000875000000262" izz="5.298749999988958e-05" ixy="-7.806255641895632e-17" iyz="-6.938893903907228e-17" ixz="1.0408340855860843e-17" />
        </inertial>
        <visual name="link1_visual">
            <origin xyz="-0.004474138301589754 0.1656199909531041 0.04999999849352971" rpy="-1.5707963267948972 -4.5507557887588e-15 -1.6344482963262228" />
            <geometry>
                <mesh filename="file://$(find arm_urdf)/meshes/link1.stl" scale="0.001 0.001 0.001" />
            </geometry>
        </visual>
        <collision name="link1_collision">
            <origin xyz="-0.004474138301589754 0.1656199909531041 0.04999999849352971" rpy="-1.5707963267948972 -4.5507557887588e-15 -1.6344482963262228" />
            <geometry>
                <mesh filename="file://$(find arm_urdf)/meshes/link1.stl" scale="0.001 0.001 0.001" />
            </geometry>
        </collision>
    </link>
    <link name="link2">
        <inertial>
            <origin xyz="-0.014769289040617651 -0.0003346506721397091 -0.08385557145011353" rpy="0.0 -0.0 0.0" />
            <mass value="0.45583838024402973" />
            <inertia ixx="0.001389932162271991" iyy="0.0014558079188540375" izz="8.465920529301257e-05" ixy="-1.5184812436688785e-05" iyz="-8.775086784630451e-05" ixz="-0.00023823770964887143" />
        </inertial>
        <visual name="link2_visual">
            <origin xyz="0.21665859287153713 -0.0134121621671121 -0.21042616110961462" rpy="-2.7900087588425464 1.38502664686012 -2.795582974074485" />
            <geometry>
                <mesh filename="file://$(find arm_urdf)/meshes/link2.stl" scale="0.001 0.001 0.001" />
            </geometry>
        </visual>
        <collision name="link2_collision">
            <origin xyz="0.21665859287153713 -0.0134121621671121 -0.21042616110961462" rpy="-2.7900087588425464 1.38502664686012 -2.795582974074485" />
            <geometry>
                <mesh filename="file://$(find arm_urdf)/meshes/link2.stl" scale="0.001 0.001 0.001" />
            </geometry>
        </collision>
    </link>
    <link name="link3">
        <inertial>
            <origin xyz="-0.06219053370049046 -0.09685681905953836 -0.0010462443786718723" rpy="3.851859888774472e-34 -7.703719777548945e-34 0.0" />
            <mass value="0.54165" />
            <inertia ixx="0.0017130104352963411" iyy="0.0007273208546288779" izz="0.002425491210074529" ixy="-0.001063586816093399" iyz="6.779097371541892e-05" ixz="4.5597392676668184e-05" />
        </inertial>
        <visual name="link3_visual">
            <origin xyz="0.15548710099672836 -0.2481442051496154 -0.009910451204884794" rpy="-1.6244271682403706 -0.034299187875663606 -2.1392603604770333" />
            <geometry>
                <mesh filename="file://$(find arm_urdf)/meshes/link3.stl" scale="0.001 0.001 0.001" />
            </geometry>
        </visual>
        <collision name="link3_collision">
            <origin xyz="0.15548710099672836 -0.2481442051496154 -0.009910451204884794" rpy="-1.6244271682403706 -0.034299187875663606 -2.1392603604770333" />
            <geometry>
                <mesh filename="file://$(find arm_urdf)/meshes/link3.stl" scale="0.001 0.001 0.001" />
            </geometry>
        </collision>
    </link>
    <link name="link4">
        <inertial>
            <origin xyz="0.03368933187098754 -0.0013716974092366386 -0.0215208698209708" rpy="4.509860003931054e-35 -0.0 1.925929944387236e-34" />
            <mass value="0.2512" />
            <inertia ixx="5.3251461562995095e-05" iyy="0.00014219896445418628" izz="0.00010598957398267467" ixy="3.627610633737121e-06" iyz="-2.3173310133798447e-06" ixz="5.691434467389697e-05" />
        </inertial>
        <visual name="link4_visual">
            <origin xyz="0.09259530638421466 0.2551975840175362 -0.020007596944642058" rpy="2.568798062729029 0.12097414696757075 -1.689161682545715" />
            <geometry>
                <mesh filename="file://$(find arm_urdf)/meshes/link4.stl" scale="0.001 0.001 0.001" />
            </geometry>
        </visual>
        <collision name="link4_collision">
            <origin xyz="0.09259530638421466 0.2551975840175362 -0.020007596944642058" rpy="2.568798062729029 0.12097414696757075 -1.689161682545715" />
            <geometry>
                <mesh filename="file://$(find arm_urdf)/meshes/link4.stl" scale="0.001 0.001 0.001" />
            </geometry>
        </collision>
    </link>
    <link name="link5">
        <inertial>
            <origin xyz="-0.02606751493819434 -0.021834663784041624 -0.06299787348098526" rpy="0.0 -0.0 1.5407439555097887e-33" />
            <mass value="0.9890999999999999" />
            <inertia ixx="0.0012214852881134441" iyy="0.0015717632709286722" izz="0.000734541440957637" ixy="-0.00023500433755998038" iyz="-0.00033565114336960044" ixz="-0.0006687578648886944" />
        </inertial>
        <visual name="link5_visual">
            <origin xyz="-0.060672634365868686 -0.2778876937654321 -0.03771286711857513" rpy="1.183001749283602 0.5541422801252738 -0.19492868944618036" />
            <geometry>
                <mesh filename="file://$(find arm_urdf)/meshes/link5.stl" scale="0.001 0.001 0.001" />
            </geometry>
        </visual>
        <collision name="link5_collision">
            <origin xyz="-0.060672634365868686 -0.2778876937654321 -0.03771286711857513" rpy="1.183001749283602 0.5541422801252738 -0.19492868944618036" />
            <geometry>
                <mesh filename="file://$(find arm_urdf)/meshes/link5.stl" scale="0.001 0.001 0.001" />
            </geometry>
        </collision>
    </link>
    <link name="link6">
        <inertial>
            <origin xyz="-0.014011199084239508 0.026805785956447965 -0.011482187082890824" rpy="0.0 -0.0 0.0" />
            <mass value="0.5163425960125627" />
            <inertia ixx="0.0004179569305815256" iyy="0.00042625023232290005" izz="0.0006448566961558266" ixy="-0.00012248907066192416" iyz="6.648848387640078e-05" ixz="1.3020451547149389e-06" />
        </inertial>
        <visual name="link6_visual">
            <origin xyz="3.763123430644555e-09 4.6647870277638506e-09 -4.404162723403715e-09" rpy="-1.851961198026746 0.07811981480371857 0.5882875181936319" />
            <geometry>
                <mesh filename="file://$(find arm_urdf)/meshes/link6.stl" scale="0.001 0.001 0.001" />
            </geometry>
        </visual>
        <collision name="link6_collision">
            <origin xyz="3.763123430644555e-09 4.6647870277638506e-09 -4.404162723403715e-09" rpy="-1.851961198026746 0.07811981480371857 0.5882875181936319" />
            <geometry>
                <mesh filename="file://$(find arm_urdf)/meshes/link6.stl" scale="0.001 0.001 0.001" />
            </geometry>
        </collision>
    </link>
    <link name="Soft_finger_1">
        <inertial>
            <origin xyz="-0.008573316285655998 -0.033996649977690085 0.01048996112137072" rpy="0.0 -0.0 0.0" />
            <mass value="0.23747567603191708" />
            <inertia ixx="0.0001768681036486141" iyy="5.588548919162328e-05" izz="0.00017235947540245045" ixy="-3.258497145529337e-05" iyz="3.9733261292140824e-05" ixz="1.0009719739093042e-05" />
        </inertial>
        <visual name="Soft_finger_1_visual">
            <origin xyz="0.0002028139506289861 -0.0005582402079608073 0.015800230708008768" rpy="2.8508098372968744 0.021280230523840652 -0.25339844459947763" />
            <geometry>
                <mesh filename="file://$(find arm_urdf)/meshes/Soft_finger_1.stl" scale="0.001 0.001 0.001" />
            </geometry>
        </visual>
        <collision name="Soft_finger_1_collision">
            <origin xyz="0.0002028139506289861 -0.0005582402079608073 0.015800230708008768" rpy="2.8508098372968744 0.021280230523840652 -0.25339844459947763" />
            <geometry>
                <mesh filename="file://$(find arm_urdf)/meshes/Soft_finger_1.stl" scale="0.001 0.001 0.001" />
            </geometry>
        </collision>
    </link>
    <link name="Soft_finger_2">
        <inertial>
            <origin xyz="-0.020170614837152278 -0.028809211488440525 0.010123673425138051" rpy="0.0 -0.0 0.0" />
            <mass value="0.23747567603191708" />
            <inertia ixx="0.00013961353495692275" iyy="9.229624339514991e-05" izz="0.00017320328989070544" ixy="-6.495389494718534e-05" iyz="3.2472565857685765e-05" ixz="2.2779917075398822e-05" />
        </inertial>
        <visual name="Soft_finger_2_visual">
            <origin xyz="-0.0013816661052049994 0.00015049294227978294 0.01575018191343862" rpy="2.8604277823579483 -0.07811981480372239 -0.5882875181936312" />
            <geometry>
                <mesh filename="file://$(find arm_urdf)/meshes/Soft_finger_2.stl" scale="0.001 0.001 0.001" />
            </geometry>
        </visual>
        <collision name="Soft_finger_2_collision">
            <origin xyz="-0.0013816661052049994 0.00015049294227978294 0.01575018191343862" rpy="2.8604277823579483 -0.07811981480372239 -0.5882875181936312" />
            <geometry>
                <mesh filename="file://$(find arm_urdf)/meshes/Soft_finger_2.stl" scale="0.001 0.001 0.001" />
            </geometry>
        </collision>
    </link>
    <link name="AX_12A_01">
        <inertial>
            <origin xyz="-0.0011270175749605116 0.010475943843512248 -0.0031672205995854344" rpy="0.0 -0.0 4.276423536147513e-50" />
            <mass value="0.2099210524614745" />
            <inertia ixx="3.884922474953201e-05" iyy="4.772392532019498e-05" izz="3.0458379644816153e-05" ixy="-4.404277445439407e-06" iyz="-6.6930956332048025e-06" ixz="-1.1718085022371925e-05" />
        </inertial>
        <visual name="AX_12A_01_visual">
            <origin xyz="-0.00803499303222015 0.007008814733963256 -0.013033718744535109" rpy="-2.028372361357468 -0.9062707528418524 0.46516832993372315" />
            <geometry>
                <mesh filename="file://$(find arm_urdf)/meshes/AX_12A_01.stl" scale="0.001 0.001 0.001" />
            </geometry>
        </visual>
        <collision name="AX_12A_01_collision">
            <origin xyz="-0.00803499303222015 0.007008814733963256 -0.013033718744535109" rpy="-2.028372361357468 -0.9062707528418524 0.46516832993372315" />
            <geometry>
                <mesh filename="file://$(find arm_urdf)/meshes/AX_12A_01.stl" scale="0.001 0.001 0.001" />
            </geometry>
        </collision>
    </link>
    <link name="AX_12A_02">
        <inertial>
            <origin xyz="0.0008329262494456202 -0.0035908928851977606 -0.0007421408839954325" rpy="0.0 -0.0 0.0" />
            <mass value="0.06044745673942447" />
            <inertia ixx="8.418184184833671e-06" iyy="1.2799562155049043e-05" izz="6.744942561227353e-06" ixy="1.417784020097193e-06" iyz="-2.480613875307375e-06" ixz="2.5922274351740378e-06" />
        </inertial>
        <visual name="AX_12A_02_visual">
            <origin xyz="-0.007394108338268879 0.0012016643323721256 0.010914810043850452" rpy="1.1132202922323264 0.9062707528418531 -0.4651683299337219" />
            <geometry>
                <mesh filename="file://$(find arm_urdf)/meshes/AX_12A_02.stl" scale="0.001 0.001 0.001" />
            </geometry>
        </visual>
        <collision name="AX_12A_02_collision">
            <origin xyz="-0.007394108338268879 0.0012016643323721256 0.010914810043850452" rpy="1.1132202922323264 0.9062707528418531 -0.4651683299337219" />
            <geometry>
                <mesh filename="file://$(find arm_urdf)/meshes/AX_12A_02.stl" scale="0.001 0.001 0.001" />
            </geometry>
        </collision>
    </link>
    <link name="AX_12A_03">
        <inertial>
            <origin xyz="0.001013957269314254 -0.00026468445306043975 0.00249223394502355" rpy="0.0 -0.0 0.0" />
            <mass value="0.05146118707510322" />
            <inertia ixx="8.384936021735984e-06" iyy="6.400972789298054e-06" izz="1.2931765666617662e-05" ixy="2.927225724450207e-06" iyz="2.3222778354273204e-06" ixz="-1.3166970365633551e-06" />
        </inertial>
        <visual name="AX_12A_03_visual">
            <origin xyz="-0.0064282679497339144 0.010404222167962019 -0.0009640605612740317" rpy="3.060293697468049 -0.2802841519126078 -0.9599733179264903" />
            <geometry>
                <mesh filename="file://$(find arm_urdf)/meshes/AX_12A_03.stl" scale="0.001 0.001 0.001" />
            </geometry>
        </visual>
        <collision name="AX_12A_03_collision">
            <origin xyz="-0.0064282679497339144 0.010404222167962019 -0.0009640605612740317" rpy="3.060293697468049 -0.2802841519126078 -0.9599733179264903" />
            <geometry>
                <mesh filename="file://$(find arm_urdf)/meshes/AX_12A_03.stl" scale="0.001 0.001 0.001" />
            </geometry>
        </collision>
    </link>
    <link name="AX_12A_04">
        <inertial>
            <origin xyz="-0.0003917960966568757 -0.004096310649258044 0.001165148060530612" rpy="0.0 -0.0 0.0" />
            <mass value="0.01314562026152729" />
            <inertia ixx="4.286675210794441e-07" iyy="7.646876955006918e-07" izz="4.5300206085656196e-07" ixy="3.243544757390231e-08" iyz="-9.645956450601843e-08" ixz="-9.225897188358203e-09" />
        </inertial>
        <visual name="AX_12A_04_visual">
            <origin xyz="-0.0006137859742558404 -0.0064172823477434806 0.0018253223004109033" rpy="1.113220292232325 0.9062707528418529 -0.46516832993372387" />
            <geometry>
                <mesh filename="file://$(find arm_urdf)/meshes/AX_12A_04.stl" scale="0.001 0.001 0.001" />
            </geometry>
        </visual>
        <collision name="AX_12A_04_collision">
            <origin xyz="-0.0006137859742558404 -0.0064172823477434806 0.0018253223004109033" rpy="1.113220292232325 0.9062707528418529 -0.46516832993372387" />
            <geometry>
                <mesh filename="file://$(find arm_urdf)/meshes/AX_12A_04.stl" scale="0.001 0.001 0.001" />
            </geometry>
        </collision>
    </link>
    <link name="Gear_Flange_Motor">
        <inertial>
            <origin xyz="-0.00759634237276245 0.005903300813793884 0.005763748370808912" rpy="0.0 -0.0 -7.703719777548943e-34" />
            <mass value="0.05643249551831147" />
            <inertia ixx="1.1221099270715407e-05" iyy="1.2106580132256045e-05" izz="1.3566209225301593e-05" ixy="3.63169488128796e-06" iyz="-3.076620204911159e-06" ixz="1.5620469385850554e-06" />
        </inertial>
        <visual name="Gear_Flange_Motor_visual">
            <origin xyz="-0.0003664402867585892 -0.0038312127939263974 0.001089746305625141" rpy="1.9039732896255348 0.5862544392453592 -3.0477712446504635" />
            <geometry>
                <mesh filename="file://$(find arm_urdf)/meshes/Gear_Flange_Motor.stl" scale="0.001 0.001 0.001" />
            </geometry>
        </visual>
        <collision name="Gear_Flange_Motor_collision">
            <origin xyz="-0.0003664402867585892 -0.0038312127939263974 0.001089746305625141" rpy="1.9039732896255348 0.5862544392453592 -3.0477712446504635" />
            <geometry>
                <mesh filename="file://$(find arm_urdf)/meshes/Gear_Flange_Motor.stl" scale="0.001 0.001 0.001" />
            </geometry>
        </collision>
    </link>
    <link name="Gear_Flange_Driven">
        <inertial>
            <origin xyz="0.0015701072260375071 -0.008444336493970894 0.0062025962706550785" rpy="0.0 -0.0 0.0" />
            <mass value="0.055055133707505116" />
            <inertia ixx="1.3435098723410532e-05" iyy="1.0943371311180821e-05" izz="1.1220134453114594e-05" ixy="1.2664992223481216e-06" iyz="4.719162529321847e-06" ixz="-7.529560055851561e-07" />
        </inertial>
        <visual name="Gear_Flange_Driven_visual">
            <origin xyz="0.0007362361982110243 -0.0019269937105750045 -0.0036985308633292035" rpy="0.2907828162929191 -0.021280230523838293 2.8881942089903077" />
            <geometry>
                <mesh filename="file://$(find arm_urdf)/meshes/Gear_Flange_Driven.stl" scale="0.001 0.001 0.001" />
            </geometry>
        </visual>
        <collision name="Gear_Flange_Driven_collision">
            <origin xyz="0.0007362361982110243 -0.0019269937105750045 -0.0036985308633292035" rpy="0.2907828162929191 -0.021280230523838293 2.8881942089903077" />
            <geometry>
                <mesh filename="file://$(find arm_urdf)/meshes/Gear_Flange_Driven.stl" scale="0.001 0.001 0.001" />
            </geometry>
        </collision>
    </link>
    <joint name="link2_link3_to_link2" type="continuous">
        <origin xyz="-0.029538580000000005 -0.0006692999999999927 -0.16771114" rpy="1.5707963267948966 -1.5707963267948966 0" />
        <parent link="link2" />
        <child link="link3" />
        <axis xyz="-0.06360899999999998 -4.353902656239713e-18 -0.997975" />
    </joint>
    <joint name="link3_link4_to_link3" type="continuous">
        <origin xyz="-0.12406301999999998 -0.19371363000000003 0.002897390000000009" rpy="-1.5707963267948966 -4.321626106750298e-18 -1.5707963267948966" />
        <parent link="link3" />
        <child link="link4" />
        <axis xyz="0.8422329999999999 -0.03429200000000001 -0.538022" />
    </joint>
    <joint name="link4_link5_to_link4" type="continuous">
        <origin xyz="0.07264080000000007 -0.004390499999999982 -0.034699259999999996" rpy="1.1275027818032317e-16 -1.5707963267948966 0" />
        <parent link="link4" />
        <child link="link5" />
        <axis xyz="0.834248 -0.16470999999999997 -0.526214" />
    </joint>
    <joint name="link1_link2_to_link1" type="continuous">
        <origin xyz="-0.0009541299999999708 -0.014969629999999973 0.05" rpy="3.141592653589793 -1.5707963267948966 0" />
        <parent link="link1" />
        <child link="link2" />
        <axis xyz="8.08751530082147e-32 0.9979749999999997 -0.063609" />
    </joint>
    <joint name="base_link_link1_to_base_link" type="continuous">
        <origin xyz="-7.400736734552993e-10 2.042416333836172e-09 0.01000000150647029" rpy="4.940492459581921e-15 -9.011888457699436e-16 -5.828670879282039e-16" />
        <parent link="base_link" />
        <child link="link1" />
        <axis xyz="0.0 0.0 1.0" />
    </joint>
    <joint name="link6_Revolute-24" type="continuous">
        <origin xyz="-0.01551356000000002 0.05984499000000007 0.002375089999999993" rpy="3.141592653589793 -3.0814879110195774e-33 -2.7755575615628914e-17" />
        <parent link="link6" />
        <child link="Gear_Flange_Driven" />
        <axis xyz="0.091609 0.2724359999999999 0.957803" />
        <mimic joint="AX_12A_04_Revolute-34" multiplier="1.0" offset="0"/>
    </joint>
    <joint name="Gear_Flange_Driven_Rigid-25" type="fixed">
        <origin xyz="0.003509530000000005 -0.0195859999999999 0.02089618999999999" rpy="1.232595164407831e-32 -7.703719777548947e-34 1.3877787807814463e-17" />
        <parent link="Gear_Flange_Driven" />
        <child link="Soft_finger_1" />
    </joint>
    <joint name="link5_link6_to_link5" type="continuous">
        <origin xyz="-0.06464874999999998 -0.04119866999999999 -0.11810252999999996" rpy="-1.5707963267948966 4.163336342344337e-17 -1.387778780781446e-17" />
        <parent link="link5" />
        <child link="link6" />
        <axis xyz="-0.55116 0.787209 -0.276629" />
    </joint>
    <joint name="link6_Rigid-30" type="fixed">
        <origin xyz="-0.03496646999999999 0.02136000000000003 -0.025080830000000026" rpy="-1.6653345369377348e-16 -3.0814879110195774e-33 -2.7755575615628914e-17" />
        <parent link="link6" />
        <child link="AX_12A_03" />
    </joint>
    <joint name="AX_12A_03_Rigid-31" type="fixed">
        <origin xyz="0.0005077899999999857 0.0008515899999999733 0.005026620000000044" rpy="1.5707963267948966 -5.551115123125783e-17 -2.7755575615628914e-17" />
        <parent link="AX_12A_03" />
        <child link="AX_12A_01" />
    </joint>
    <joint name="AX_12A_01_Rigid-32" type="fixed">
        <origin xyz="-0.002015399999999943 0.021071659999999996 -0.005993599999999972" rpy="3.141592653589793 -0.0 -5.551115123125783e-17" />
        <parent link="AX_12A_01" />
        <child link="AX_12A_02" />
    </joint>
    <joint name="AX_12A_02_Rigid-33" type="fixed">
        <origin xyz="-0.00764603000000001 -0.0014322900000000162 0.011664010000000075" rpy="0.0 -2.7755575615628914e-17 -5.551115123125783e-17" />
        <parent link="AX_12A_02" />
        <child link="AX_12A_04" />
    </joint>
    <joint name="AX_12A_04_Revolute-34" type="continuous">
        <origin xyz="-0.0005863000000000085 -0.006129940000000005 0.0017435899999999548" rpy="0.0 -2.775557561562892e-17 8.552847072295028e-50" />
        <parent link="AX_12A_04" />
        <child link="Gear_Flange_Motor" />
        <axis xyz="-0.09160899999999993 -0.957803 0.27243599999999996" />
    </joint>
    <joint name="Gear_Flange_Motor_Rigid-35" type="fixed">
        <origin xyz="-0.016761230000000005 0.020872840000000004 0.012687659999999995" rpy="-1.5707963267948966 2.7755575615628914e-17 1.1102230246251565e-16" />
        <parent link="Gear_Flange_Motor" />
        <child link="Soft_finger_2" />
    </joint>
</robot>